<!DOCTYPE html>
<html lang="en">

<head>
    <meta charset="UTF-8">
    <title>Promise.prototype.catch()</title>
    <script>
    //Promise.prototype.catch方法是.then(null, rejection)的别名，用于指定发生错误时的回调函数。
    //reject方法的作用，等同于抛出错误。
    //catch方法返回的还是一个 Promise 对象，因此后面还可以接着调用then方法。后面then()的错误与前面无关了，前面也捕获不到了

    //catch方法之中，还能再抛出错误。
     
    
    promise
        .then(function(data) { //cb
            // success
        })
        .catch(function(err) {
            // error
        });

    //这种写法可以捕获前面then方法执行中的错误，也更接近同步的写法（try/catch）。因此，建议总是使用catch方法，而不使用then方法的第二个参数。

    //如果没有使用catch方法指定错误处理的回调函数，Promise对象抛出的错误不会传递到外层代码，即不会有任何反应。注意，Chrome浏览器不遵守这条规定，它会抛出错误。



    var promise = new Promise(function(resolve, reject) {
        resolve('ok');
        setTimeout(function() {
            throw new Error('test')
        }, 0)
    });
    promise.then(function(value) {
        console.log(value)
    });
    // ok
    // Uncaught Error: test
     
    //上面代码中，Promise 指定在下一轮“事件循环”再抛出错误，结果由于没有指定使用try...catch语句，就冒泡到最外层，成了未捕获的错误。因为此时，Promise的函数体已经运行结束了，所以这个错误是在Promise函数体外抛出的(即.catch()无法捕获到)。
    





    </script>
</head>

<body>
</body>

</html>
